[2025-03-27T11:55:16.975+0000] {local_task_job_runner.py:123} INFO - ::group::Pre task execution logs
[2025-03-27T11:55:16.990+0000] {taskinstance.py:2614} INFO - Dependencies all met for dep_context=non-requeueable deps ti=<TaskInstance: my_dag.add_capsules_to_table manual__2025-03-27T11:55:15.325151+00:00 [queued]>
[2025-03-27T11:55:16.996+0000] {taskinstance.py:2614} INFO - Dependencies all met for dep_context=requeueable deps ti=<TaskInstance: my_dag.add_capsules_to_table manual__2025-03-27T11:55:15.325151+00:00 [queued]>
[2025-03-27T11:55:16.996+0000] {taskinstance.py:2867} INFO - Starting attempt 1 of 1
[2025-03-27T11:55:17.011+0000] {taskinstance.py:2890} INFO - Executing <Task(PythonOperator): add_capsules_to_table> on 2025-03-27 11:55:15.325151+00:00
[2025-03-27T11:55:17.018+0000] {warnings.py:112} WARNING - /home/***/.local/lib/python3.12/site-packages/***/task/task_runner/standard_task_runner.py:70: DeprecationWarning: This process (pid=97) is multi-threaded, use of fork() may lead to deadlocks in the child.
  pid = os.fork()

[2025-03-27T11:55:17.019+0000] {standard_task_runner.py:72} INFO - Started process 99 to run task
[2025-03-27T11:55:17.019+0000] {standard_task_runner.py:104} INFO - Running: ['***', 'tasks', 'run', 'my_dag', 'add_capsules_to_table', 'manual__2025-03-27T11:55:15.325151+00:00', '--job-id', '24', '--raw', '--subdir', 'DAGS_FOLDER/main_dag.py', '--cfg-path', '/tmp/tmpnspkpwt3']
[2025-03-27T11:55:17.020+0000] {standard_task_runner.py:105} INFO - Job 24: Subtask add_capsules_to_table
[2025-03-27T11:55:17.250+0000] {task_command.py:467} INFO - Running <TaskInstance: my_dag.add_capsules_to_table manual__2025-03-27T11:55:15.325151+00:00 [running]> on host 2753c0b03e32
[2025-03-27T11:55:17.322+0000] {taskinstance.py:3134} INFO - Exporting env vars: AIRFLOW_CTX_DAG_OWNER='***' AIRFLOW_CTX_DAG_ID='my_dag' AIRFLOW_CTX_TASK_ID='add_capsules_to_table' AIRFLOW_CTX_EXECUTION_DATE='2025-03-27T11:55:15.325151+00:00' AIRFLOW_CTX_TRY_NUMBER='1' AIRFLOW_CTX_DAG_RUN_ID='manual__2025-03-27T11:55:15.325151+00:00'
[2025-03-27T11:55:17.322+0000] {logging_mixin.py:190} INFO - Task instance is in running state
[2025-03-27T11:55:17.323+0000] {logging_mixin.py:190} INFO -  Previous state of the Task instance: queued
[2025-03-27T11:55:17.323+0000] {logging_mixin.py:190} INFO - Current task name:add_capsules_to_table state:running start_date:2025-03-27 11:55:16.990645+00:00
[2025-03-27T11:55:17.323+0000] {logging_mixin.py:190} INFO - Dag name:my_dag and current dag run status:running
[2025-03-27T11:55:17.324+0000] {taskinstance.py:732} INFO - ::endgroup::
[2025-03-27T11:55:17.338+0000] {taskinstance.py:3313} ERROR - Task failed with exception
Traceback (most recent call last):
  File "/home/airflow/.local/lib/python3.12/site-packages/airflow/models/taskinstance.py", line 768, in _execute_task
    result = _execute_callable(context=context, **execute_callable_kwargs)
             ^^^^^^^^^^^^^^^^^^^^^^^^^^^^^^^^^^^^^^^^^^^^^^^^^^^^^^^^^^^^^
  File "/home/airflow/.local/lib/python3.12/site-packages/airflow/models/taskinstance.py", line 734, in _execute_callable
    return ExecutionCallableRunner(
           ^^^^^^^^^^^^^^^^^^^^^^^^
  File "/home/airflow/.local/lib/python3.12/site-packages/airflow/utils/operator_helpers.py", line 252, in run
    return self.func(*args, **kwargs)
           ^^^^^^^^^^^^^^^^^^^^^^^^^^
  File "/home/airflow/.local/lib/python3.12/site-packages/airflow/models/baseoperator.py", line 424, in wrapper
    return func(self, *args, **kwargs)
           ^^^^^^^^^^^^^^^^^^^^^^^^^^^
  File "/home/airflow/.local/lib/python3.12/site-packages/airflow/operators/python.py", line 238, in execute
    return_value = self.execute_callable()
                   ^^^^^^^^^^^^^^^^^^^^^^^
  File "/home/airflow/.local/lib/python3.12/site-packages/airflow/operators/python.py", line 256, in execute_callable
    return runner.run(*self.op_args, **self.op_kwargs)
           ^^^^^^^^^^^^^^^^^^^^^^^^^^^^^^^^^^^^^^^^^^^
  File "/home/airflow/.local/lib/python3.12/site-packages/airflow/utils/operator_helpers.py", line 252, in run
    return self.func(*args, **kwargs)
           ^^^^^^^^^^^^^^^^^^^^^^^^^^
  File "/opt/airflow/dags/main_dag.py", line 17, in load_data
    engine = hook.get_sqlalchemy_engine()
             ^^^^^^^^^^^^^^^^^^^^^^^^^^^^
  File "/home/airflow/.local/lib/python3.12/site-packages/airflow/providers/common/sql/hooks/sql.py", line 253, in get_sqlalchemy_engine
    url = self.sqlalchemy_url
          ^^^^^^^^^^^^^^^^^^^
  File "/home/airflow/.local/lib/python3.12/site-packages/airflow/providers/postgres/hooks/postgres.py", line 112, in sqlalchemy_url
    conn = self.connection
           ^^^^^^^^^^^^^^^
  File "/home/airflow/.local/lib/python3.12/site-packages/airflow/providers/common/sql/hooks/sql.py", line 180, in connection
    self._connection = self.get_connection(self.get_conn_id())
                       ^^^^^^^^^^^^^^^^^^^^^^^^^^^^^^^^^^^^^^^
  File "/home/airflow/.local/lib/python3.12/site-packages/airflow/hooks/base.py", line 83, in get_connection
    conn = Connection.get_connection_from_secrets(conn_id)
           ^^^^^^^^^^^^^^^^^^^^^^^^^^^^^^^^^^^^^^^^^^^^^^^
  File "/home/airflow/.local/lib/python3.12/site-packages/airflow/models/connection.py", line 537, in get_connection_from_secrets
    raise AirflowNotFoundException(f"The conn_id `{conn_id}` isn't defined")
airflow.exceptions.AirflowNotFoundException: The conn_id `postgres_db` isn't defined
[2025-03-27T11:55:17.343+0000] {logging_mixin.py:190} INFO - Task instance in failure state
[2025-03-27T11:55:17.344+0000] {logging_mixin.py:190} INFO - Task start:2025-03-27 11:55:16.990645+00:00 end:2025-03-27 11:55:17.343457+00:00 duration:0.352812
[2025-03-27T11:55:17.344+0000] {logging_mixin.py:190} INFO - Task:<Task(PythonOperator): add_capsules_to_table> dag:<DAG: my_dag> dagrun:<DagRun my_dag @ 2025-03-27 11:55:15.325151+00:00: manual__2025-03-27T11:55:15.325151+00:00, state:running, queued_at: 2025-03-27 11:55:15.334574+00:00. externally triggered: True>
[2025-03-27T11:55:17.344+0000] {logging_mixin.py:190} INFO - Failure caused by The conn_id `postgres_db` isn't defined
[2025-03-27T11:55:17.345+0000] {taskinstance.py:1226} INFO - Marking task as FAILED. dag_id=my_dag, task_id=add_capsules_to_table, run_id=manual__2025-03-27T11:55:15.325151+00:00, execution_date=20250327T115515, start_date=20250327T115516, end_date=20250327T115517
[2025-03-27T11:55:17.366+0000] {taskinstance.py:341} INFO - ::group::Post task execution logs
[2025-03-27T11:55:17.366+0000] {standard_task_runner.py:124} ERROR - Failed to execute job 24 for task add_capsules_to_table (The conn_id `postgres_db` isn't defined; 99)
Traceback (most recent call last):
  File "/home/airflow/.local/lib/python3.12/site-packages/airflow/task/task_runner/standard_task_runner.py", line 117, in _start_by_fork
    ret = args.func(args, dag=self.dag)
          ^^^^^^^^^^^^^^^^^^^^^^^^^^^^^
  File "/home/airflow/.local/lib/python3.12/site-packages/airflow/cli/cli_config.py", line 49, in command
    return func(*args, **kwargs)
           ^^^^^^^^^^^^^^^^^^^^^
  File "/home/airflow/.local/lib/python3.12/site-packages/airflow/utils/cli.py", line 116, in wrapper
    return f(*args, **kwargs)
           ^^^^^^^^^^^^^^^^^^
  File "/home/airflow/.local/lib/python3.12/site-packages/airflow/cli/commands/task_command.py", line 483, in task_run
    task_return_code = _run_task_by_selected_method(args, _dag, ti)
                       ^^^^^^^^^^^^^^^^^^^^^^^^^^^^^^^^^^^^^^^^^^^^
  File "/home/airflow/.local/lib/python3.12/site-packages/airflow/cli/commands/task_command.py", line 256, in _run_task_by_selected_method
    return _run_raw_task(args, ti)
           ^^^^^^^^^^^^^^^^^^^^^^^
  File "/home/airflow/.local/lib/python3.12/site-packages/airflow/cli/commands/task_command.py", line 341, in _run_raw_task
    return ti._run_raw_task(
           ^^^^^^^^^^^^^^^^^
  File "/home/airflow/.local/lib/python3.12/site-packages/airflow/utils/session.py", line 97, in wrapper
    return func(*args, session=session, **kwargs)
           ^^^^^^^^^^^^^^^^^^^^^^^^^^^^^^^^^^^^^^
  File "/home/airflow/.local/lib/python3.12/site-packages/airflow/models/taskinstance.py", line 3006, in _run_raw_task
    return _run_raw_task(
           ^^^^^^^^^^^^^^
  File "/home/airflow/.local/lib/python3.12/site-packages/airflow/models/taskinstance.py", line 274, in _run_raw_task
    TaskInstance._execute_task_with_callbacks(
  File "/home/airflow/.local/lib/python3.12/site-packages/airflow/models/taskinstance.py", line 3161, in _execute_task_with_callbacks
    result = self._execute_task(context, task_orig)
             ^^^^^^^^^^^^^^^^^^^^^^^^^^^^^^^^^^^^^^
  File "/home/airflow/.local/lib/python3.12/site-packages/airflow/models/taskinstance.py", line 3185, in _execute_task
    return _execute_task(self, context, task_orig)
           ^^^^^^^^^^^^^^^^^^^^^^^^^^^^^^^^^^^^^^^
  File "/home/airflow/.local/lib/python3.12/site-packages/airflow/models/taskinstance.py", line 768, in _execute_task
    result = _execute_callable(context=context, **execute_callable_kwargs)
             ^^^^^^^^^^^^^^^^^^^^^^^^^^^^^^^^^^^^^^^^^^^^^^^^^^^^^^^^^^^^^
  File "/home/airflow/.local/lib/python3.12/site-packages/airflow/models/taskinstance.py", line 734, in _execute_callable
    return ExecutionCallableRunner(
           ^^^^^^^^^^^^^^^^^^^^^^^^
  File "/home/airflow/.local/lib/python3.12/site-packages/airflow/utils/operator_helpers.py", line 252, in run
    return self.func(*args, **kwargs)
           ^^^^^^^^^^^^^^^^^^^^^^^^^^
  File "/home/airflow/.local/lib/python3.12/site-packages/airflow/models/baseoperator.py", line 424, in wrapper
    return func(self, *args, **kwargs)
           ^^^^^^^^^^^^^^^^^^^^^^^^^^^
  File "/home/airflow/.local/lib/python3.12/site-packages/airflow/operators/python.py", line 238, in execute
    return_value = self.execute_callable()
                   ^^^^^^^^^^^^^^^^^^^^^^^
  File "/home/airflow/.local/lib/python3.12/site-packages/airflow/operators/python.py", line 256, in execute_callable
    return runner.run(*self.op_args, **self.op_kwargs)
           ^^^^^^^^^^^^^^^^^^^^^^^^^^^^^^^^^^^^^^^^^^^
  File "/home/airflow/.local/lib/python3.12/site-packages/airflow/utils/operator_helpers.py", line 252, in run
    return self.func(*args, **kwargs)
           ^^^^^^^^^^^^^^^^^^^^^^^^^^
  File "/opt/airflow/dags/main_dag.py", line 17, in load_data
    engine = hook.get_sqlalchemy_engine()
             ^^^^^^^^^^^^^^^^^^^^^^^^^^^^
  File "/home/airflow/.local/lib/python3.12/site-packages/airflow/providers/common/sql/hooks/sql.py", line 253, in get_sqlalchemy_engine
    url = self.sqlalchemy_url
          ^^^^^^^^^^^^^^^^^^^
  File "/home/airflow/.local/lib/python3.12/site-packages/airflow/providers/postgres/hooks/postgres.py", line 112, in sqlalchemy_url
    conn = self.connection
           ^^^^^^^^^^^^^^^
  File "/home/airflow/.local/lib/python3.12/site-packages/airflow/providers/common/sql/hooks/sql.py", line 180, in connection
    self._connection = self.get_connection(self.get_conn_id())
                       ^^^^^^^^^^^^^^^^^^^^^^^^^^^^^^^^^^^^^^^
  File "/home/airflow/.local/lib/python3.12/site-packages/airflow/hooks/base.py", line 83, in get_connection
    conn = Connection.get_connection_from_secrets(conn_id)
           ^^^^^^^^^^^^^^^^^^^^^^^^^^^^^^^^^^^^^^^^^^^^^^^
  File "/home/airflow/.local/lib/python3.12/site-packages/airflow/models/connection.py", line 537, in get_connection_from_secrets
    raise AirflowNotFoundException(f"The conn_id `{conn_id}` isn't defined")
airflow.exceptions.AirflowNotFoundException: The conn_id `postgres_db` isn't defined
[2025-03-27T11:55:17.405+0000] {local_task_job_runner.py:266} INFO - Task exited with return code 1
[2025-03-27T11:55:17.586+0000] {taskinstance.py:3901} INFO - 0 downstream tasks scheduled from follow-on schedule check
[2025-03-27T11:55:17.597+0000] {local_task_job_runner.py:245} INFO - ::endgroup::
