[2025-03-27T12:10:12.064+0000] {local_task_job_runner.py:123} INFO - ::group::Pre task execution logs
[2025-03-27T12:10:12.085+0000] {taskinstance.py:2614} INFO - Dependencies all met for dep_context=non-requeueable deps ti=<TaskInstance: my_dag.add_launches_to_table manual__2025-03-27T12:09:57.337293+00:00 [queued]>
[2025-03-27T12:10:12.095+0000] {taskinstance.py:2614} INFO - Dependencies all met for dep_context=requeueable deps ti=<TaskInstance: my_dag.add_launches_to_table manual__2025-03-27T12:09:57.337293+00:00 [queued]>
[2025-03-27T12:10:12.095+0000] {taskinstance.py:2867} INFO - Starting attempt 1 of 1
[2025-03-27T12:10:12.110+0000] {taskinstance.py:2890} INFO - Executing <Task(PythonOperator): add_launches_to_table> on 2025-03-27 12:09:57.337293+00:00
[2025-03-27T12:10:12.117+0000] {warnings.py:112} WARNING - /home/***/.local/lib/python3.12/site-packages/***/task/task_runner/standard_task_runner.py:70: DeprecationWarning: This process (pid=377) is multi-threaded, use of fork() may lead to deadlocks in the child.
  pid = os.fork()

[2025-03-27T12:10:12.119+0000] {standard_task_runner.py:72} INFO - Started process 379 to run task
[2025-03-27T12:10:12.119+0000] {standard_task_runner.py:104} INFO - Running: ['***', 'tasks', 'run', 'my_dag', 'add_launches_to_table', 'manual__2025-03-27T12:09:57.337293+00:00', '--job-id', '47', '--raw', '--subdir', 'DAGS_FOLDER/main_dag.py', '--cfg-path', '/tmp/tmpe5_zcdtq']
[2025-03-27T12:10:12.120+0000] {standard_task_runner.py:105} INFO - Job 47: Subtask add_launches_to_table
[2025-03-27T12:10:12.402+0000] {task_command.py:467} INFO - Running <TaskInstance: my_dag.add_launches_to_table manual__2025-03-27T12:09:57.337293+00:00 [running]> on host 2753c0b03e32
[2025-03-27T12:10:12.471+0000] {taskinstance.py:3134} INFO - Exporting env vars: AIRFLOW_CTX_DAG_OWNER='***' AIRFLOW_CTX_DAG_ID='my_dag' AIRFLOW_CTX_TASK_ID='add_launches_to_table' AIRFLOW_CTX_EXECUTION_DATE='2025-03-27T12:09:57.337293+00:00' AIRFLOW_CTX_TRY_NUMBER='1' AIRFLOW_CTX_DAG_RUN_ID='manual__2025-03-27T12:09:57.337293+00:00'
[2025-03-27T12:10:12.472+0000] {logging_mixin.py:190} INFO - Task instance is in running state
[2025-03-27T12:10:12.472+0000] {logging_mixin.py:190} INFO -  Previous state of the Task instance: queued
[2025-03-27T12:10:12.473+0000] {logging_mixin.py:190} INFO - Current task name:add_launches_to_table state:running start_date:2025-03-27 12:10:12.086167+00:00
[2025-03-27T12:10:12.473+0000] {logging_mixin.py:190} INFO - Dag name:my_dag and current dag run status:running
[2025-03-27T12:10:12.473+0000] {taskinstance.py:732} INFO - ::endgroup::
[2025-03-27T12:10:12.482+0000] {base.py:84} INFO - Retrieving connection 'postgres_db'
[2025-03-27T12:10:17.756+0000] {taskinstance.py:3313} ERROR - Task failed with exception
Traceback (most recent call last):
  File "/home/airflow/.local/lib/python3.12/site-packages/sqlalchemy/engine/base.py", line 1910, in _execute_context
    self.dialect.do_execute(
  File "/home/airflow/.local/lib/python3.12/site-packages/sqlalchemy/engine/default.py", line 736, in do_execute
    cursor.execute(statement, parameters)
psycopg2.ProgrammingError: can't adapt type 'dict'

The above exception was the direct cause of the following exception:

Traceback (most recent call last):
  File "/opt/airflow/dags/main_dag.py", line 24, in load_data
    session.commit()
  File "/home/airflow/.local/lib/python3.12/site-packages/sqlalchemy/orm/session.py", line 1454, in commit
    self._transaction.commit(_to_root=self.future)
  File "/home/airflow/.local/lib/python3.12/site-packages/sqlalchemy/orm/session.py", line 832, in commit
    self._prepare_impl()
  File "/home/airflow/.local/lib/python3.12/site-packages/sqlalchemy/orm/session.py", line 811, in _prepare_impl
    self.session.flush()
  File "/home/airflow/.local/lib/python3.12/site-packages/sqlalchemy/orm/session.py", line 3449, in flush
    self._flush(objects)
  File "/home/airflow/.local/lib/python3.12/site-packages/sqlalchemy/orm/session.py", line 3588, in _flush
    with util.safe_reraise():
         ^^^^^^^^^^^^^^^^^^^
  File "/home/airflow/.local/lib/python3.12/site-packages/sqlalchemy/util/langhelpers.py", line 70, in __exit__
    compat.raise_(
  File "/home/airflow/.local/lib/python3.12/site-packages/sqlalchemy/util/compat.py", line 211, in raise_
    raise exception
  File "/home/airflow/.local/lib/python3.12/site-packages/sqlalchemy/orm/session.py", line 3549, in _flush
    flush_context.execute()
  File "/home/airflow/.local/lib/python3.12/site-packages/sqlalchemy/orm/unitofwork.py", line 456, in execute
    rec.execute(self)
  File "/home/airflow/.local/lib/python3.12/site-packages/sqlalchemy/orm/unitofwork.py", line 630, in execute
    util.preloaded.orm_persistence.save_obj(
  File "/home/airflow/.local/lib/python3.12/site-packages/sqlalchemy/orm/persistence.py", line 245, in save_obj
    _emit_insert_statements(
  File "/home/airflow/.local/lib/python3.12/site-packages/sqlalchemy/orm/persistence.py", line 1097, in _emit_insert_statements
    c = connection._execute_20(
        ^^^^^^^^^^^^^^^^^^^^^^^
  File "/home/airflow/.local/lib/python3.12/site-packages/sqlalchemy/engine/base.py", line 1710, in _execute_20
    return meth(self, args_10style, kwargs_10style, execution_options)
           ^^^^^^^^^^^^^^^^^^^^^^^^^^^^^^^^^^^^^^^^^^^^^^^^^^^^^^^^^^^
  File "/home/airflow/.local/lib/python3.12/site-packages/sqlalchemy/sql/elements.py", line 334, in _execute_on_connection
    return connection._execute_clauseelement(
           ^^^^^^^^^^^^^^^^^^^^^^^^^^^^^^^^^^
  File "/home/airflow/.local/lib/python3.12/site-packages/sqlalchemy/engine/base.py", line 1577, in _execute_clauseelement
    ret = self._execute_context(
          ^^^^^^^^^^^^^^^^^^^^^^
  File "/home/airflow/.local/lib/python3.12/site-packages/sqlalchemy/engine/base.py", line 1953, in _execute_context
    self._handle_dbapi_exception(
  File "/home/airflow/.local/lib/python3.12/site-packages/sqlalchemy/engine/base.py", line 2134, in _handle_dbapi_exception
    util.raise_(
  File "/home/airflow/.local/lib/python3.12/site-packages/sqlalchemy/util/compat.py", line 211, in raise_
    raise exception
  File "/home/airflow/.local/lib/python3.12/site-packages/sqlalchemy/engine/base.py", line 1910, in _execute_context
    self.dialect.do_execute(
  File "/home/airflow/.local/lib/python3.12/site-packages/sqlalchemy/engine/default.py", line 736, in do_execute
    cursor.execute(statement, parameters)
sqlalchemy.exc.ProgrammingError: (psycopg2.ProgrammingError) can't adapt type 'dict'
[SQL: INSERT INTO launches (fairings, links, static_fire_date_utc, static_fire_date_unix, net, "window", rocket, success, failures, details, crew, ships, capsules, payloads, launchpad, flight_number, name, date_utc, date_unix, date_local, date_precision, upcoming, cores, id) VALUES (%(fairings)s, %(links)s, %(static_fire_date_utc)s, %(static_fire_date_unix)s, %(net)s, %(window)s, %(rocket)s, %(success)s, %(failures)s::VARCHAR[], %(details)s, %(crew)s::VARCHAR[], %(ships)s::VARCHAR[], %(capsules)s::VARCHAR[], %(payloads)s::VARCHAR[], %(launchpad)s, %(flight_number)s, %(name)s, %(date_utc)s, %(date_unix)s, %(date_local)s, %(date_precision)s, %(upcoming)s, %(cores)s::VARCHAR[], %(id)s)]
[parameters: {'fairings': '{"reused": false, "recovery_attempt": false, "recovered": false, "ships": []}', 'links': '{"patch": {"small": "https://images2.imgbox.com/94/f2/NN6Ph45r_o.png", "large": "https://images2.imgbox.com/5b/02/QcxHUb5V_o.png"}, "reddit": {"campa ... (203 characters truncated) ... 88", "article": "https://www.space.com/2196-spacex-inaugural-falcon-1-rocket-lost-launch.html", "wikipedia": "https://en.wikipedia.org/wiki/DemoSat"}', 'static_fire_date_utc': '2006-03-17T00:00:00.000Z', 'static_fire_date_unix': 1142553600, 'net': False, 'window': 0, 'rocket': '5e9d0d95eda69955f709d1eb', 'success': False, 'failures': [{'time': 33, 'altitude': None, 'reason': 'merlin engine failure'}], 'details': 'Engine failure at 33 seconds and loss of vehicle', 'crew': [], 'ships': [], 'capsules': [], 'payloads': ['5eb0e4b5b6c3bb0006eeb1e1'], 'launchpad': '5e9e4502f5090995de566f86', 'flight_number': 1, 'name': 'FalconSat', 'date_utc': '2006-03-24T22:30:00.000Z', 'date_unix': 1143239400, 'date_local': '2006-03-25T10:30:00+12:00', 'date_precision': 'hour', 'upcoming': False, 'cores': [{'core': '5e9e289df35918033d3b2623', 'flight': 1, 'gridfins': False, 'legs': False, 'reused': False, 'landing_attempt': False, 'landing_success': None, 'landing_type': None, 'landpad': None}], 'id': '5eb87cd9ffd86e000604b32a'}]
(Background on this error at: https://sqlalche.me/e/14/f405)

During handling of the above exception, another exception occurred:

Traceback (most recent call last):
  File "/home/airflow/.local/lib/python3.12/site-packages/airflow/models/taskinstance.py", line 768, in _execute_task
    result = _execute_callable(context=context, **execute_callable_kwargs)
             ^^^^^^^^^^^^^^^^^^^^^^^^^^^^^^^^^^^^^^^^^^^^^^^^^^^^^^^^^^^^^
  File "/home/airflow/.local/lib/python3.12/site-packages/airflow/models/taskinstance.py", line 734, in _execute_callable
    return ExecutionCallableRunner(
           ^^^^^^^^^^^^^^^^^^^^^^^^
  File "/home/airflow/.local/lib/python3.12/site-packages/airflow/utils/operator_helpers.py", line 252, in run
    return self.func(*args, **kwargs)
           ^^^^^^^^^^^^^^^^^^^^^^^^^^
  File "/home/airflow/.local/lib/python3.12/site-packages/airflow/models/baseoperator.py", line 424, in wrapper
    return func(self, *args, **kwargs)
           ^^^^^^^^^^^^^^^^^^^^^^^^^^^
  File "/home/airflow/.local/lib/python3.12/site-packages/airflow/operators/python.py", line 238, in execute
    return_value = self.execute_callable()
                   ^^^^^^^^^^^^^^^^^^^^^^^
  File "/home/airflow/.local/lib/python3.12/site-packages/airflow/operators/python.py", line 256, in execute_callable
    return runner.run(*self.op_args, **self.op_kwargs)
           ^^^^^^^^^^^^^^^^^^^^^^^^^^^^^^^^^^^^^^^^^^^
  File "/home/airflow/.local/lib/python3.12/site-packages/airflow/utils/operator_helpers.py", line 252, in run
    return self.func(*args, **kwargs)
           ^^^^^^^^^^^^^^^^^^^^^^^^^^
  File "/opt/airflow/dags/main_dag.py", line 29, in load_data
    raise Exception(f"Ошикбка {e}")
Exception: Ошикбка (psycopg2.ProgrammingError) can't adapt type 'dict'
[SQL: INSERT INTO launches (fairings, links, static_fire_date_utc, static_fire_date_unix, net, "window", rocket, success, failures, details, crew, ships, capsules, payloads, launchpad, flight_number, name, date_utc, date_unix, date_local, date_precision, upcoming, cores, id) VALUES (%(fairings)s, %(links)s, %(static_fire_date_utc)s, %(static_fire_date_unix)s, %(net)s, %(window)s, %(rocket)s, %(success)s, %(failures)s::VARCHAR[], %(details)s, %(crew)s::VARCHAR[], %(ships)s::VARCHAR[], %(capsules)s::VARCHAR[], %(payloads)s::VARCHAR[], %(launchpad)s, %(flight_number)s, %(name)s, %(date_utc)s, %(date_unix)s, %(date_local)s, %(date_precision)s, %(upcoming)s, %(cores)s::VARCHAR[], %(id)s)]
[parameters: {'fairings': '{"reused": false, "recovery_attempt": false, "recovered": false, "ships": []}', 'links': '{"patch": {"small": "https://images2.imgbox.com/94/f2/NN6Ph45r_o.png", "large": "https://images2.imgbox.com/5b/02/QcxHUb5V_o.png"}, "reddit": {"campa ... (203 characters truncated) ... 88", "article": "https://www.space.com/2196-spacex-inaugural-falcon-1-rocket-lost-launch.html", "wikipedia": "https://en.wikipedia.org/wiki/DemoSat"}', 'static_fire_date_utc': '2006-03-17T00:00:00.000Z', 'static_fire_date_unix': 1142553600, 'net': False, 'window': 0, 'rocket': '5e9d0d95eda69955f709d1eb', 'success': False, 'failures': [{'time': 33, 'altitude': None, 'reason': 'merlin engine failure'}], 'details': 'Engine failure at 33 seconds and loss of vehicle', 'crew': [], 'ships': [], 'capsules': [], 'payloads': ['5eb0e4b5b6c3bb0006eeb1e1'], 'launchpad': '5e9e4502f5090995de566f86', 'flight_number': 1, 'name': 'FalconSat', 'date_utc': '2006-03-24T22:30:00.000Z', 'date_unix': 1143239400, 'date_local': '2006-03-25T10:30:00+12:00', 'date_precision': 'hour', 'upcoming': False, 'cores': [{'core': '5e9e289df35918033d3b2623', 'flight': 1, 'gridfins': False, 'legs': False, 'reused': False, 'landing_attempt': False, 'landing_success': None, 'landing_type': None, 'landpad': None}], 'id': '5eb87cd9ffd86e000604b32a'}]
(Background on this error at: https://sqlalche.me/e/14/f405)
[2025-03-27T12:10:17.773+0000] {logging_mixin.py:190} INFO - Task instance in failure state
[2025-03-27T12:10:17.774+0000] {logging_mixin.py:190} INFO - Task start:2025-03-27 12:10:12.086167+00:00 end:2025-03-27 12:10:17.773306+00:00 duration:5.687139
[2025-03-27T12:10:17.774+0000] {logging_mixin.py:190} INFO - Task:<Task(PythonOperator): add_launches_to_table> dag:<DAG: my_dag> dagrun:<DagRun my_dag @ 2025-03-27 12:09:57.337293+00:00: manual__2025-03-27T12:09:57.337293+00:00, state:running, queued_at: 2025-03-27 12:09:57.346374+00:00. externally triggered: True>
[2025-03-27T12:10:17.774+0000] {logging_mixin.py:190} INFO - Failure caused by Ошикбка (psycopg2.ProgrammingError) can't adapt type 'dict'
[SQL: INSERT INTO launches (fairings, links, static_fire_date_utc, static_fire_date_unix, net, "window", rocket, success, failures, details, crew, ships, capsules, payloads, launchpad, flight_number, name, date_utc, date_unix, date_local, date_precision, upcoming, cores, id) VALUES (%(fairings)s, %(links)s, %(static_fire_date_utc)s, %(static_fire_date_unix)s, %(net)s, %(window)s, %(rocket)s, %(success)s, %(failures)s::VARCHAR[], %(details)s, %(crew)s::VARCHAR[], %(ships)s::VARCHAR[], %(capsules)s::VARCHAR[], %(payloads)s::VARCHAR[], %(launchpad)s, %(flight_number)s, %(name)s, %(date_utc)s, %(date_unix)s, %(date_local)s, %(date_precision)s, %(upcoming)s, %(cores)s::VARCHAR[], %(id)s)]
[parameters: {'fairings': '{"reused": false, "recovery_attempt": false, "recovered": false, "ships": []}', 'links': '{"patch": {"small": "https://images2.imgbox.com/94/f2/NN6Ph45r_o.png", "large": "https://images2.imgbox.com/5b/02/QcxHUb5V_o.png"}, "reddit": {"campa ... (203 characters truncated) ... 88", "article": "https://www.space.com/2196-spacex-inaugural-falcon-1-rocket-lost-launch.html", "wikipedia": "https://en.wikipedia.org/wiki/DemoSat"}', 'static_fire_date_utc': '2006-03-17T00:00:00.000Z', 'static_fire_date_unix': 1142553600, 'net': False, 'window': 0, 'rocket': '5e9d0d95eda69955f709d1eb', 'success': False, 'failures': [{'time': 33, 'altitude': None, 'reason': 'merlin engine failure'}], 'details': 'Engine failure at 33 seconds and loss of vehicle', 'crew': [], 'ships': [], 'capsules': [], 'payloads': ['5eb0e4b5b6c3bb0006eeb1e1'], 'launchpad': '5e9e4502f5090995de566f86', 'flight_number': 1, 'name': 'FalconSat', 'date_utc': '2006-03-24T22:30:00.000Z', 'date_unix': 1143239400, 'date_local': '2006-03-25T10:30:00+12:00', 'date_precision': 'hour', 'upcoming': False, 'cores': [{'core': '5e9e289df35918033d3b2623', 'flight': 1, 'gridfins': False, 'legs': False, 'reused': False, 'landing_attempt': False, 'landing_success': None, 'landing_type': None, 'landpad': None}], 'id': '5eb87cd9ffd86e000604b32a'}]
(Background on this error at: https://sqlalche.me/e/14/f405)
[2025-03-27T12:10:17.775+0000] {taskinstance.py:1226} INFO - Marking task as FAILED. dag_id=my_dag, task_id=add_launches_to_table, run_id=manual__2025-03-27T12:09:57.337293+00:00, execution_date=20250327T120957, start_date=20250327T121012, end_date=20250327T121017
[2025-03-27T12:10:17.801+0000] {taskinstance.py:341} INFO - ::group::Post task execution logs
[2025-03-27T12:10:17.802+0000] {standard_task_runner.py:124} ERROR - Failed to execute job 47 for task add_launches_to_table (Ошикбка (psycopg2.ProgrammingError) can't adapt type 'dict'
[SQL: INSERT INTO launches (fairings, links, static_fire_date_utc, static_fire_date_unix, net, "window", rocket, success, failures, details, crew, ships, capsules, payloads, launchpad, flight_number, name, date_utc, date_unix, date_local, date_precision, upcoming, cores, id) VALUES (%(fairings)s, %(links)s, %(static_fire_date_utc)s, %(static_fire_date_unix)s, %(net)s, %(window)s, %(rocket)s, %(success)s, %(failures)s::VARCHAR[], %(details)s, %(crew)s::VARCHAR[], %(ships)s::VARCHAR[], %(capsules)s::VARCHAR[], %(payloads)s::VARCHAR[], %(launchpad)s, %(flight_number)s, %(name)s, %(date_utc)s, %(date_unix)s, %(date_local)s, %(date_precision)s, %(upcoming)s, %(cores)s::VARCHAR[], %(id)s)]
[parameters: {'fairings': '{"reused": false, "recovery_attempt": false, "recovered": false, "ships": []}', 'links': '{"patch": {"small": "https://images2.imgbox.com/94/f2/NN6Ph45r_o.png", "large": "https://images2.imgbox.com/5b/02/QcxHUb5V_o.png"}, "reddit": {"campa ... (203 characters truncated) ... 88", "article": "https://www.space.com/2196-spacex-inaugural-falcon-1-rocket-lost-launch.html", "wikipedia": "https://en.wikipedia.org/wiki/DemoSat"}', 'static_fire_date_utc': '2006-03-17T00:00:00.000Z', 'static_fire_date_unix': 1142553600, 'net': False, 'window': 0, 'rocket': '5e9d0d95eda69955f709d1eb', 'success': False, 'failures': [{'time': 33, 'altitude': None, 'reason': 'merlin engine failure'}], 'details': 'Engine failure at 33 seconds and loss of vehicle', 'crew': [], 'ships': [], 'capsules': [], 'payloads': ['5eb0e4b5b6c3bb0006eeb1e1'], 'launchpad': '5e9e4502f5090995de566f86', 'flight_number': 1, 'name': 'FalconSat', 'date_utc': '2006-03-24T22:30:00.000Z', 'date_unix': 1143239400, 'date_local': '2006-03-25T10:30:00+12:00', 'date_precision': 'hour', 'upcoming': False, 'cores': [{'core': '5e9e289df35918033d3b2623', 'flight': 1, 'gridfins': False, 'legs': False, 'reused': False, 'landing_attempt': False, 'landing_success': None, 'landing_type': None, 'landpad': None}], 'id': '5eb87cd9ffd86e000604b32a'}]
(Background on this error at: https://sqlalche.me/e/14/f405); 379)
Traceback (most recent call last):
  File "/home/airflow/.local/lib/python3.12/site-packages/sqlalchemy/engine/base.py", line 1910, in _execute_context
    self.dialect.do_execute(
  File "/home/airflow/.local/lib/python3.12/site-packages/sqlalchemy/engine/default.py", line 736, in do_execute
    cursor.execute(statement, parameters)
psycopg2.ProgrammingError: can't adapt type 'dict'

The above exception was the direct cause of the following exception:

Traceback (most recent call last):
  File "/opt/airflow/dags/main_dag.py", line 24, in load_data
    session.commit()
  File "/home/airflow/.local/lib/python3.12/site-packages/sqlalchemy/orm/session.py", line 1454, in commit
    self._transaction.commit(_to_root=self.future)
  File "/home/airflow/.local/lib/python3.12/site-packages/sqlalchemy/orm/session.py", line 832, in commit
    self._prepare_impl()
  File "/home/airflow/.local/lib/python3.12/site-packages/sqlalchemy/orm/session.py", line 811, in _prepare_impl
    self.session.flush()
  File "/home/airflow/.local/lib/python3.12/site-packages/sqlalchemy/orm/session.py", line 3449, in flush
    self._flush(objects)
  File "/home/airflow/.local/lib/python3.12/site-packages/sqlalchemy/orm/session.py", line 3588, in _flush
    with util.safe_reraise():
         ^^^^^^^^^^^^^^^^^^^
  File "/home/airflow/.local/lib/python3.12/site-packages/sqlalchemy/util/langhelpers.py", line 70, in __exit__
    compat.raise_(
  File "/home/airflow/.local/lib/python3.12/site-packages/sqlalchemy/util/compat.py", line 211, in raise_
    raise exception
  File "/home/airflow/.local/lib/python3.12/site-packages/sqlalchemy/orm/session.py", line 3549, in _flush
    flush_context.execute()
  File "/home/airflow/.local/lib/python3.12/site-packages/sqlalchemy/orm/unitofwork.py", line 456, in execute
    rec.execute(self)
  File "/home/airflow/.local/lib/python3.12/site-packages/sqlalchemy/orm/unitofwork.py", line 630, in execute
    util.preloaded.orm_persistence.save_obj(
  File "/home/airflow/.local/lib/python3.12/site-packages/sqlalchemy/orm/persistence.py", line 245, in save_obj
    _emit_insert_statements(
  File "/home/airflow/.local/lib/python3.12/site-packages/sqlalchemy/orm/persistence.py", line 1097, in _emit_insert_statements
    c = connection._execute_20(
        ^^^^^^^^^^^^^^^^^^^^^^^
  File "/home/airflow/.local/lib/python3.12/site-packages/sqlalchemy/engine/base.py", line 1710, in _execute_20
    return meth(self, args_10style, kwargs_10style, execution_options)
           ^^^^^^^^^^^^^^^^^^^^^^^^^^^^^^^^^^^^^^^^^^^^^^^^^^^^^^^^^^^
  File "/home/airflow/.local/lib/python3.12/site-packages/sqlalchemy/sql/elements.py", line 334, in _execute_on_connection
    return connection._execute_clauseelement(
           ^^^^^^^^^^^^^^^^^^^^^^^^^^^^^^^^^^
  File "/home/airflow/.local/lib/python3.12/site-packages/sqlalchemy/engine/base.py", line 1577, in _execute_clauseelement
    ret = self._execute_context(
          ^^^^^^^^^^^^^^^^^^^^^^
  File "/home/airflow/.local/lib/python3.12/site-packages/sqlalchemy/engine/base.py", line 1953, in _execute_context
    self._handle_dbapi_exception(
  File "/home/airflow/.local/lib/python3.12/site-packages/sqlalchemy/engine/base.py", line 2134, in _handle_dbapi_exception
    util.raise_(
  File "/home/airflow/.local/lib/python3.12/site-packages/sqlalchemy/util/compat.py", line 211, in raise_
    raise exception
  File "/home/airflow/.local/lib/python3.12/site-packages/sqlalchemy/engine/base.py", line 1910, in _execute_context
    self.dialect.do_execute(
  File "/home/airflow/.local/lib/python3.12/site-packages/sqlalchemy/engine/default.py", line 736, in do_execute
    cursor.execute(statement, parameters)
sqlalchemy.exc.ProgrammingError: (psycopg2.ProgrammingError) can't adapt type 'dict'
[SQL: INSERT INTO launches (fairings, links, static_fire_date_utc, static_fire_date_unix, net, "window", rocket, success, failures, details, crew, ships, capsules, payloads, launchpad, flight_number, name, date_utc, date_unix, date_local, date_precision, upcoming, cores, id) VALUES (%(fairings)s, %(links)s, %(static_fire_date_utc)s, %(static_fire_date_unix)s, %(net)s, %(window)s, %(rocket)s, %(success)s, %(failures)s::VARCHAR[], %(details)s, %(crew)s::VARCHAR[], %(ships)s::VARCHAR[], %(capsules)s::VARCHAR[], %(payloads)s::VARCHAR[], %(launchpad)s, %(flight_number)s, %(name)s, %(date_utc)s, %(date_unix)s, %(date_local)s, %(date_precision)s, %(upcoming)s, %(cores)s::VARCHAR[], %(id)s)]
[parameters: {'fairings': '{"reused": false, "recovery_attempt": false, "recovered": false, "ships": []}', 'links': '{"patch": {"small": "https://images2.imgbox.com/94/f2/NN6Ph45r_o.png", "large": "https://images2.imgbox.com/5b/02/QcxHUb5V_o.png"}, "reddit": {"campa ... (203 characters truncated) ... 88", "article": "https://www.space.com/2196-spacex-inaugural-falcon-1-rocket-lost-launch.html", "wikipedia": "https://en.wikipedia.org/wiki/DemoSat"}', 'static_fire_date_utc': '2006-03-17T00:00:00.000Z', 'static_fire_date_unix': 1142553600, 'net': False, 'window': 0, 'rocket': '5e9d0d95eda69955f709d1eb', 'success': False, 'failures': [{'time': 33, 'altitude': None, 'reason': 'merlin engine failure'}], 'details': 'Engine failure at 33 seconds and loss of vehicle', 'crew': [], 'ships': [], 'capsules': [], 'payloads': ['5eb0e4b5b6c3bb0006eeb1e1'], 'launchpad': '5e9e4502f5090995de566f86', 'flight_number': 1, 'name': 'FalconSat', 'date_utc': '2006-03-24T22:30:00.000Z', 'date_unix': 1143239400, 'date_local': '2006-03-25T10:30:00+12:00', 'date_precision': 'hour', 'upcoming': False, 'cores': [{'core': '5e9e289df35918033d3b2623', 'flight': 1, 'gridfins': False, 'legs': False, 'reused': False, 'landing_attempt': False, 'landing_success': None, 'landing_type': None, 'landpad': None}], 'id': '5eb87cd9ffd86e000604b32a'}]
(Background on this error at: https://sqlalche.me/e/14/f405)

During handling of the above exception, another exception occurred:

Traceback (most recent call last):
  File "/home/airflow/.local/lib/python3.12/site-packages/airflow/task/task_runner/standard_task_runner.py", line 117, in _start_by_fork
    ret = args.func(args, dag=self.dag)
          ^^^^^^^^^^^^^^^^^^^^^^^^^^^^^
  File "/home/airflow/.local/lib/python3.12/site-packages/airflow/cli/cli_config.py", line 49, in command
    return func(*args, **kwargs)
           ^^^^^^^^^^^^^^^^^^^^^
  File "/home/airflow/.local/lib/python3.12/site-packages/airflow/utils/cli.py", line 116, in wrapper
    return f(*args, **kwargs)
           ^^^^^^^^^^^^^^^^^^
  File "/home/airflow/.local/lib/python3.12/site-packages/airflow/cli/commands/task_command.py", line 483, in task_run
    task_return_code = _run_task_by_selected_method(args, _dag, ti)
                       ^^^^^^^^^^^^^^^^^^^^^^^^^^^^^^^^^^^^^^^^^^^^
  File "/home/airflow/.local/lib/python3.12/site-packages/airflow/cli/commands/task_command.py", line 256, in _run_task_by_selected_method
    return _run_raw_task(args, ti)
           ^^^^^^^^^^^^^^^^^^^^^^^
  File "/home/airflow/.local/lib/python3.12/site-packages/airflow/cli/commands/task_command.py", line 341, in _run_raw_task
    return ti._run_raw_task(
           ^^^^^^^^^^^^^^^^^
  File "/home/airflow/.local/lib/python3.12/site-packages/airflow/utils/session.py", line 97, in wrapper
    return func(*args, session=session, **kwargs)
           ^^^^^^^^^^^^^^^^^^^^^^^^^^^^^^^^^^^^^^
  File "/home/airflow/.local/lib/python3.12/site-packages/airflow/models/taskinstance.py", line 3006, in _run_raw_task
    return _run_raw_task(
           ^^^^^^^^^^^^^^
  File "/home/airflow/.local/lib/python3.12/site-packages/airflow/models/taskinstance.py", line 274, in _run_raw_task
    TaskInstance._execute_task_with_callbacks(
  File "/home/airflow/.local/lib/python3.12/site-packages/airflow/models/taskinstance.py", line 3161, in _execute_task_with_callbacks
    result = self._execute_task(context, task_orig)
             ^^^^^^^^^^^^^^^^^^^^^^^^^^^^^^^^^^^^^^
  File "/home/airflow/.local/lib/python3.12/site-packages/airflow/models/taskinstance.py", line 3185, in _execute_task
    return _execute_task(self, context, task_orig)
           ^^^^^^^^^^^^^^^^^^^^^^^^^^^^^^^^^^^^^^^
  File "/home/airflow/.local/lib/python3.12/site-packages/airflow/models/taskinstance.py", line 768, in _execute_task
    result = _execute_callable(context=context, **execute_callable_kwargs)
             ^^^^^^^^^^^^^^^^^^^^^^^^^^^^^^^^^^^^^^^^^^^^^^^^^^^^^^^^^^^^^
  File "/home/airflow/.local/lib/python3.12/site-packages/airflow/models/taskinstance.py", line 734, in _execute_callable
    return ExecutionCallableRunner(
           ^^^^^^^^^^^^^^^^^^^^^^^^
  File "/home/airflow/.local/lib/python3.12/site-packages/airflow/utils/operator_helpers.py", line 252, in run
    return self.func(*args, **kwargs)
           ^^^^^^^^^^^^^^^^^^^^^^^^^^
  File "/home/airflow/.local/lib/python3.12/site-packages/airflow/models/baseoperator.py", line 424, in wrapper
    return func(self, *args, **kwargs)
           ^^^^^^^^^^^^^^^^^^^^^^^^^^^
  File "/home/airflow/.local/lib/python3.12/site-packages/airflow/operators/python.py", line 238, in execute
    return_value = self.execute_callable()
                   ^^^^^^^^^^^^^^^^^^^^^^^
  File "/home/airflow/.local/lib/python3.12/site-packages/airflow/operators/python.py", line 256, in execute_callable
    return runner.run(*self.op_args, **self.op_kwargs)
           ^^^^^^^^^^^^^^^^^^^^^^^^^^^^^^^^^^^^^^^^^^^
  File "/home/airflow/.local/lib/python3.12/site-packages/airflow/utils/operator_helpers.py", line 252, in run
    return self.func(*args, **kwargs)
           ^^^^^^^^^^^^^^^^^^^^^^^^^^
  File "/opt/airflow/dags/main_dag.py", line 29, in load_data
    raise Exception(f"Ошикбка {e}")
Exception: Ошикбка (psycopg2.ProgrammingError) can't adapt type 'dict'
[SQL: INSERT INTO launches (fairings, links, static_fire_date_utc, static_fire_date_unix, net, "window", rocket, success, failures, details, crew, ships, capsules, payloads, launchpad, flight_number, name, date_utc, date_unix, date_local, date_precision, upcoming, cores, id) VALUES (%(fairings)s, %(links)s, %(static_fire_date_utc)s, %(static_fire_date_unix)s, %(net)s, %(window)s, %(rocket)s, %(success)s, %(failures)s::VARCHAR[], %(details)s, %(crew)s::VARCHAR[], %(ships)s::VARCHAR[], %(capsules)s::VARCHAR[], %(payloads)s::VARCHAR[], %(launchpad)s, %(flight_number)s, %(name)s, %(date_utc)s, %(date_unix)s, %(date_local)s, %(date_precision)s, %(upcoming)s, %(cores)s::VARCHAR[], %(id)s)]
[parameters: {'fairings': '{"reused": false, "recovery_attempt": false, "recovered": false, "ships": []}', 'links': '{"patch": {"small": "https://images2.imgbox.com/94/f2/NN6Ph45r_o.png", "large": "https://images2.imgbox.com/5b/02/QcxHUb5V_o.png"}, "reddit": {"campa ... (203 characters truncated) ... 88", "article": "https://www.space.com/2196-spacex-inaugural-falcon-1-rocket-lost-launch.html", "wikipedia": "https://en.wikipedia.org/wiki/DemoSat"}', 'static_fire_date_utc': '2006-03-17T00:00:00.000Z', 'static_fire_date_unix': 1142553600, 'net': False, 'window': 0, 'rocket': '5e9d0d95eda69955f709d1eb', 'success': False, 'failures': [{'time': 33, 'altitude': None, 'reason': 'merlin engine failure'}], 'details': 'Engine failure at 33 seconds and loss of vehicle', 'crew': [], 'ships': [], 'capsules': [], 'payloads': ['5eb0e4b5b6c3bb0006eeb1e1'], 'launchpad': '5e9e4502f5090995de566f86', 'flight_number': 1, 'name': 'FalconSat', 'date_utc': '2006-03-24T22:30:00.000Z', 'date_unix': 1143239400, 'date_local': '2006-03-25T10:30:00+12:00', 'date_precision': 'hour', 'upcoming': False, 'cores': [{'core': '5e9e289df35918033d3b2623', 'flight': 1, 'gridfins': False, 'legs': False, 'reused': False, 'landing_attempt': False, 'landing_success': None, 'landing_type': None, 'landpad': None}], 'id': '5eb87cd9ffd86e000604b32a'}]
(Background on this error at: https://sqlalche.me/e/14/f405)
[2025-03-27T12:10:17.861+0000] {local_task_job_runner.py:266} INFO - Task exited with return code 1
[2025-03-27T12:10:17.883+0000] {taskinstance.py:3901} INFO - 0 downstream tasks scheduled from follow-on schedule check
[2025-03-27T12:10:17.887+0000] {local_task_job_runner.py:245} INFO - ::endgroup::
