[2025-03-27T11:57:29.014+0000] {local_task_job_runner.py:123} INFO - ::group::Pre task execution logs
[2025-03-27T11:57:29.029+0000] {taskinstance.py:2614} INFO - Dependencies all met for dep_context=non-requeueable deps ti=<TaskInstance: my_dag.add_capsules_to_table manual__2025-03-27T11:57:27.271965+00:00 [queued]>
[2025-03-27T11:57:29.035+0000] {taskinstance.py:2614} INFO - Dependencies all met for dep_context=requeueable deps ti=<TaskInstance: my_dag.add_capsules_to_table manual__2025-03-27T11:57:27.271965+00:00 [queued]>
[2025-03-27T11:57:29.035+0000] {taskinstance.py:2867} INFO - Starting attempt 1 of 1
[2025-03-27T11:57:29.047+0000] {taskinstance.py:2890} INFO - Executing <Task(PythonOperator): add_capsules_to_table> on 2025-03-27 11:57:27.271965+00:00
[2025-03-27T11:57:29.053+0000] {warnings.py:112} WARNING - /home/***/.local/lib/python3.12/site-packages/***/task/task_runner/standard_task_runner.py:70: DeprecationWarning: This process (pid=132) is multi-threaded, use of fork() may lead to deadlocks in the child.
  pid = os.fork()

[2025-03-27T11:57:29.055+0000] {standard_task_runner.py:72} INFO - Started process 134 to run task
[2025-03-27T11:57:29.055+0000] {standard_task_runner.py:104} INFO - Running: ['***', 'tasks', 'run', 'my_dag', 'add_capsules_to_table', 'manual__2025-03-27T11:57:27.271965+00:00', '--job-id', '26', '--raw', '--subdir', 'DAGS_FOLDER/main_dag.py', '--cfg-path', '/tmp/tmpykpmnfdt']
[2025-03-27T11:57:29.056+0000] {standard_task_runner.py:105} INFO - Job 26: Subtask add_capsules_to_table
[2025-03-27T11:57:29.285+0000] {task_command.py:467} INFO - Running <TaskInstance: my_dag.add_capsules_to_table manual__2025-03-27T11:57:27.271965+00:00 [running]> on host 2753c0b03e32
[2025-03-27T11:57:29.345+0000] {taskinstance.py:3134} INFO - Exporting env vars: AIRFLOW_CTX_DAG_OWNER='***' AIRFLOW_CTX_DAG_ID='my_dag' AIRFLOW_CTX_TASK_ID='add_capsules_to_table' AIRFLOW_CTX_EXECUTION_DATE='2025-03-27T11:57:27.271965+00:00' AIRFLOW_CTX_TRY_NUMBER='1' AIRFLOW_CTX_DAG_RUN_ID='manual__2025-03-27T11:57:27.271965+00:00'
[2025-03-27T11:57:29.346+0000] {logging_mixin.py:190} INFO - Task instance is in running state
[2025-03-27T11:57:29.346+0000] {logging_mixin.py:190} INFO -  Previous state of the Task instance: queued
[2025-03-27T11:57:29.346+0000] {logging_mixin.py:190} INFO - Current task name:add_capsules_to_table state:running start_date:2025-03-27 11:57:29.029704+00:00
[2025-03-27T11:57:29.346+0000] {logging_mixin.py:190} INFO - Dag name:my_dag and current dag run status:running
[2025-03-27T11:57:29.347+0000] {taskinstance.py:732} INFO - ::endgroup::
[2025-03-27T11:57:29.354+0000] {base.py:84} INFO - Retrieving connection 'postgres_db'
[2025-03-27T11:57:33.568+0000] {taskinstance.py:3313} ERROR - Task failed with exception
Traceback (most recent call last):
  File "/opt/airflow/dags/main_dag.py", line 23, in load_data
    session.add(func(js))
                ^^^^^^^^
  File "/opt/airflow/dags/value_in_database.py", line 11, in get_capsules
    reuse_count = sat_json["reuse_count"],
                  ~~~~~~~~^^^^^^^^^^^^^^^
TypeError: string indices must be integers, not 'str'

During handling of the above exception, another exception occurred:

Traceback (most recent call last):
  File "/home/airflow/.local/lib/python3.12/site-packages/airflow/models/taskinstance.py", line 768, in _execute_task
    result = _execute_callable(context=context, **execute_callable_kwargs)
             ^^^^^^^^^^^^^^^^^^^^^^^^^^^^^^^^^^^^^^^^^^^^^^^^^^^^^^^^^^^^^
  File "/home/airflow/.local/lib/python3.12/site-packages/airflow/models/taskinstance.py", line 734, in _execute_callable
    return ExecutionCallableRunner(
           ^^^^^^^^^^^^^^^^^^^^^^^^
  File "/home/airflow/.local/lib/python3.12/site-packages/airflow/utils/operator_helpers.py", line 252, in run
    return self.func(*args, **kwargs)
           ^^^^^^^^^^^^^^^^^^^^^^^^^^
  File "/home/airflow/.local/lib/python3.12/site-packages/airflow/models/baseoperator.py", line 424, in wrapper
    return func(self, *args, **kwargs)
           ^^^^^^^^^^^^^^^^^^^^^^^^^^^
  File "/home/airflow/.local/lib/python3.12/site-packages/airflow/operators/python.py", line 238, in execute
    return_value = self.execute_callable()
                   ^^^^^^^^^^^^^^^^^^^^^^^
  File "/home/airflow/.local/lib/python3.12/site-packages/airflow/operators/python.py", line 256, in execute_callable
    return runner.run(*self.op_args, **self.op_kwargs)
           ^^^^^^^^^^^^^^^^^^^^^^^^^^^^^^^^^^^^^^^^^^^
  File "/home/airflow/.local/lib/python3.12/site-packages/airflow/utils/operator_helpers.py", line 252, in run
    return self.func(*args, **kwargs)
           ^^^^^^^^^^^^^^^^^^^^^^^^^^
  File "/opt/airflow/dags/main_dag.py", line 29, in load_data
    raise Exception(f"Ошикбка {e}")
Exception: Ошикбка string indices must be integers, not 'str'
[2025-03-27T11:57:33.577+0000] {logging_mixin.py:190} INFO - Task instance in failure state
[2025-03-27T11:57:33.577+0000] {logging_mixin.py:190} INFO - Task start:2025-03-27 11:57:29.029704+00:00 end:2025-03-27 11:57:33.576904+00:00 duration:4.5472
[2025-03-27T11:57:33.578+0000] {logging_mixin.py:190} INFO - Task:<Task(PythonOperator): add_capsules_to_table> dag:<DAG: my_dag> dagrun:<DagRun my_dag @ 2025-03-27 11:57:27.271965+00:00: manual__2025-03-27T11:57:27.271965+00:00, state:running, queued_at: 2025-03-27 11:57:27.280109+00:00. externally triggered: True>
[2025-03-27T11:57:33.578+0000] {logging_mixin.py:190} INFO - Failure caused by Ошикбка string indices must be integers, not 'str'
[2025-03-27T11:57:33.578+0000] {taskinstance.py:1226} INFO - Marking task as FAILED. dag_id=my_dag, task_id=add_capsules_to_table, run_id=manual__2025-03-27T11:57:27.271965+00:00, execution_date=20250327T115727, start_date=20250327T115729, end_date=20250327T115733
[2025-03-27T11:57:33.602+0000] {taskinstance.py:341} INFO - ::group::Post task execution logs
[2025-03-27T11:57:33.602+0000] {standard_task_runner.py:124} ERROR - Failed to execute job 26 for task add_capsules_to_table (Ошикбка string indices must be integers, not 'str'; 134)
Traceback (most recent call last):
  File "/opt/airflow/dags/main_dag.py", line 23, in load_data
    session.add(func(js))
                ^^^^^^^^
  File "/opt/airflow/dags/value_in_database.py", line 11, in get_capsules
    reuse_count = sat_json["reuse_count"],
                  ~~~~~~~~^^^^^^^^^^^^^^^
TypeError: string indices must be integers, not 'str'

During handling of the above exception, another exception occurred:

Traceback (most recent call last):
  File "/home/airflow/.local/lib/python3.12/site-packages/airflow/task/task_runner/standard_task_runner.py", line 117, in _start_by_fork
    ret = args.func(args, dag=self.dag)
          ^^^^^^^^^^^^^^^^^^^^^^^^^^^^^
  File "/home/airflow/.local/lib/python3.12/site-packages/airflow/cli/cli_config.py", line 49, in command
    return func(*args, **kwargs)
           ^^^^^^^^^^^^^^^^^^^^^
  File "/home/airflow/.local/lib/python3.12/site-packages/airflow/utils/cli.py", line 116, in wrapper
    return f(*args, **kwargs)
           ^^^^^^^^^^^^^^^^^^
  File "/home/airflow/.local/lib/python3.12/site-packages/airflow/cli/commands/task_command.py", line 483, in task_run
    task_return_code = _run_task_by_selected_method(args, _dag, ti)
                       ^^^^^^^^^^^^^^^^^^^^^^^^^^^^^^^^^^^^^^^^^^^^
  File "/home/airflow/.local/lib/python3.12/site-packages/airflow/cli/commands/task_command.py", line 256, in _run_task_by_selected_method
    return _run_raw_task(args, ti)
           ^^^^^^^^^^^^^^^^^^^^^^^
  File "/home/airflow/.local/lib/python3.12/site-packages/airflow/cli/commands/task_command.py", line 341, in _run_raw_task
    return ti._run_raw_task(
           ^^^^^^^^^^^^^^^^^
  File "/home/airflow/.local/lib/python3.12/site-packages/airflow/utils/session.py", line 97, in wrapper
    return func(*args, session=session, **kwargs)
           ^^^^^^^^^^^^^^^^^^^^^^^^^^^^^^^^^^^^^^
  File "/home/airflow/.local/lib/python3.12/site-packages/airflow/models/taskinstance.py", line 3006, in _run_raw_task
    return _run_raw_task(
           ^^^^^^^^^^^^^^
  File "/home/airflow/.local/lib/python3.12/site-packages/airflow/models/taskinstance.py", line 274, in _run_raw_task
    TaskInstance._execute_task_with_callbacks(
  File "/home/airflow/.local/lib/python3.12/site-packages/airflow/models/taskinstance.py", line 3161, in _execute_task_with_callbacks
    result = self._execute_task(context, task_orig)
             ^^^^^^^^^^^^^^^^^^^^^^^^^^^^^^^^^^^^^^
  File "/home/airflow/.local/lib/python3.12/site-packages/airflow/models/taskinstance.py", line 3185, in _execute_task
    return _execute_task(self, context, task_orig)
           ^^^^^^^^^^^^^^^^^^^^^^^^^^^^^^^^^^^^^^^
  File "/home/airflow/.local/lib/python3.12/site-packages/airflow/models/taskinstance.py", line 768, in _execute_task
    result = _execute_callable(context=context, **execute_callable_kwargs)
             ^^^^^^^^^^^^^^^^^^^^^^^^^^^^^^^^^^^^^^^^^^^^^^^^^^^^^^^^^^^^^
  File "/home/airflow/.local/lib/python3.12/site-packages/airflow/models/taskinstance.py", line 734, in _execute_callable
    return ExecutionCallableRunner(
           ^^^^^^^^^^^^^^^^^^^^^^^^
  File "/home/airflow/.local/lib/python3.12/site-packages/airflow/utils/operator_helpers.py", line 252, in run
    return self.func(*args, **kwargs)
           ^^^^^^^^^^^^^^^^^^^^^^^^^^
  File "/home/airflow/.local/lib/python3.12/site-packages/airflow/models/baseoperator.py", line 424, in wrapper
    return func(self, *args, **kwargs)
           ^^^^^^^^^^^^^^^^^^^^^^^^^^^
  File "/home/airflow/.local/lib/python3.12/site-packages/airflow/operators/python.py", line 238, in execute
    return_value = self.execute_callable()
                   ^^^^^^^^^^^^^^^^^^^^^^^
  File "/home/airflow/.local/lib/python3.12/site-packages/airflow/operators/python.py", line 256, in execute_callable
    return runner.run(*self.op_args, **self.op_kwargs)
           ^^^^^^^^^^^^^^^^^^^^^^^^^^^^^^^^^^^^^^^^^^^
  File "/home/airflow/.local/lib/python3.12/site-packages/airflow/utils/operator_helpers.py", line 252, in run
    return self.func(*args, **kwargs)
           ^^^^^^^^^^^^^^^^^^^^^^^^^^
  File "/opt/airflow/dags/main_dag.py", line 29, in load_data
    raise Exception(f"Ошикбка {e}")
Exception: Ошикбка string indices must be integers, not 'str'
[2025-03-27T11:57:33.626+0000] {local_task_job_runner.py:266} INFO - Task exited with return code 1
[2025-03-27T11:57:33.811+0000] {taskinstance.py:3901} INFO - 0 downstream tasks scheduled from follow-on schedule check
[2025-03-27T11:57:33.822+0000] {local_task_job_runner.py:245} INFO - ::endgroup::
