[2025-03-27T12:06:48.099+0000] {local_task_job_runner.py:123} INFO - ::group::Pre task execution logs
[2025-03-27T12:06:48.114+0000] {taskinstance.py:2614} INFO - Dependencies all met for dep_context=non-requeueable deps ti=<TaskInstance: my_dag.add_capsules_to_table manual__2025-03-27T12:06:46.350909+00:00 [queued]>
[2025-03-27T12:06:48.120+0000] {taskinstance.py:2614} INFO - Dependencies all met for dep_context=requeueable deps ti=<TaskInstance: my_dag.add_capsules_to_table manual__2025-03-27T12:06:46.350909+00:00 [queued]>
[2025-03-27T12:06:48.120+0000] {taskinstance.py:2867} INFO - Starting attempt 1 of 1
[2025-03-27T12:06:48.133+0000] {taskinstance.py:2890} INFO - Executing <Task(PythonOperator): add_capsules_to_table> on 2025-03-27 12:06:46.350909+00:00
[2025-03-27T12:06:48.139+0000] {warnings.py:112} WARNING - /home/***/.local/lib/python3.12/site-packages/***/task/task_runner/standard_task_runner.py:70: DeprecationWarning: This process (pid=275) is multi-threaded, use of fork() may lead to deadlocks in the child.
  pid = os.fork()

[2025-03-27T12:06:48.140+0000] {standard_task_runner.py:72} INFO - Started process 277 to run task
[2025-03-27T12:06:48.141+0000] {standard_task_runner.py:104} INFO - Running: ['***', 'tasks', 'run', 'my_dag', 'add_capsules_to_table', 'manual__2025-03-27T12:06:46.350909+00:00', '--job-id', '32', '--raw', '--subdir', 'DAGS_FOLDER/main_dag.py', '--cfg-path', '/tmp/tmperq4cvoa']
[2025-03-27T12:06:48.142+0000] {standard_task_runner.py:105} INFO - Job 32: Subtask add_capsules_to_table
[2025-03-27T12:06:48.367+0000] {task_command.py:467} INFO - Running <TaskInstance: my_dag.add_capsules_to_table manual__2025-03-27T12:06:46.350909+00:00 [running]> on host 2753c0b03e32
[2025-03-27T12:06:48.439+0000] {taskinstance.py:3134} INFO - Exporting env vars: AIRFLOW_CTX_DAG_OWNER='***' AIRFLOW_CTX_DAG_ID='my_dag' AIRFLOW_CTX_TASK_ID='add_capsules_to_table' AIRFLOW_CTX_EXECUTION_DATE='2025-03-27T12:06:46.350909+00:00' AIRFLOW_CTX_TRY_NUMBER='1' AIRFLOW_CTX_DAG_RUN_ID='manual__2025-03-27T12:06:46.350909+00:00'
[2025-03-27T12:06:48.439+0000] {logging_mixin.py:190} INFO - Task instance is in running state
[2025-03-27T12:06:48.440+0000] {logging_mixin.py:190} INFO -  Previous state of the Task instance: queued
[2025-03-27T12:06:48.440+0000] {logging_mixin.py:190} INFO - Current task name:add_capsules_to_table state:running start_date:2025-03-27 12:06:48.114613+00:00
[2025-03-27T12:06:48.441+0000] {logging_mixin.py:190} INFO - Dag name:my_dag and current dag run status:running
[2025-03-27T12:06:48.441+0000] {taskinstance.py:732} INFO - ::endgroup::
[2025-03-27T12:06:48.449+0000] {base.py:84} INFO - Retrieving connection 'postgres_db'
[2025-03-27T12:06:50.581+0000] {taskinstance.py:3313} ERROR - Task failed with exception
Traceback (most recent call last):
  File "/home/airflow/.local/lib/python3.12/site-packages/sqlalchemy/engine/base.py", line 1910, in _execute_context
    self.dialect.do_execute(
  File "/home/airflow/.local/lib/python3.12/site-packages/sqlalchemy/engine/default.py", line 736, in do_execute
    cursor.execute(statement, parameters)
psycopg2.errors.UniqueViolation: duplicate key value violates unique constraint "capsules_pkey"
DETAIL:  Key (id)=(5e9e2c5bf35918ed873b2664) already exists.


The above exception was the direct cause of the following exception:

Traceback (most recent call last):
  File "/opt/airflow/dags/main_dag.py", line 24, in load_data
    session.commit()
  File "/home/airflow/.local/lib/python3.12/site-packages/sqlalchemy/orm/session.py", line 1454, in commit
    self._transaction.commit(_to_root=self.future)
  File "/home/airflow/.local/lib/python3.12/site-packages/sqlalchemy/orm/session.py", line 832, in commit
    self._prepare_impl()
  File "/home/airflow/.local/lib/python3.12/site-packages/sqlalchemy/orm/session.py", line 811, in _prepare_impl
    self.session.flush()
  File "/home/airflow/.local/lib/python3.12/site-packages/sqlalchemy/orm/session.py", line 3449, in flush
    self._flush(objects)
  File "/home/airflow/.local/lib/python3.12/site-packages/sqlalchemy/orm/session.py", line 3588, in _flush
    with util.safe_reraise():
         ^^^^^^^^^^^^^^^^^^^
  File "/home/airflow/.local/lib/python3.12/site-packages/sqlalchemy/util/langhelpers.py", line 70, in __exit__
    compat.raise_(
  File "/home/airflow/.local/lib/python3.12/site-packages/sqlalchemy/util/compat.py", line 211, in raise_
    raise exception
  File "/home/airflow/.local/lib/python3.12/site-packages/sqlalchemy/orm/session.py", line 3549, in _flush
    flush_context.execute()
  File "/home/airflow/.local/lib/python3.12/site-packages/sqlalchemy/orm/unitofwork.py", line 456, in execute
    rec.execute(self)
  File "/home/airflow/.local/lib/python3.12/site-packages/sqlalchemy/orm/unitofwork.py", line 630, in execute
    util.preloaded.orm_persistence.save_obj(
  File "/home/airflow/.local/lib/python3.12/site-packages/sqlalchemy/orm/persistence.py", line 245, in save_obj
    _emit_insert_statements(
  File "/home/airflow/.local/lib/python3.12/site-packages/sqlalchemy/orm/persistence.py", line 1097, in _emit_insert_statements
    c = connection._execute_20(
        ^^^^^^^^^^^^^^^^^^^^^^^
  File "/home/airflow/.local/lib/python3.12/site-packages/sqlalchemy/engine/base.py", line 1710, in _execute_20
    return meth(self, args_10style, kwargs_10style, execution_options)
           ^^^^^^^^^^^^^^^^^^^^^^^^^^^^^^^^^^^^^^^^^^^^^^^^^^^^^^^^^^^
  File "/home/airflow/.local/lib/python3.12/site-packages/sqlalchemy/sql/elements.py", line 334, in _execute_on_connection
    return connection._execute_clauseelement(
           ^^^^^^^^^^^^^^^^^^^^^^^^^^^^^^^^^^
  File "/home/airflow/.local/lib/python3.12/site-packages/sqlalchemy/engine/base.py", line 1577, in _execute_clauseelement
    ret = self._execute_context(
          ^^^^^^^^^^^^^^^^^^^^^^
  File "/home/airflow/.local/lib/python3.12/site-packages/sqlalchemy/engine/base.py", line 1953, in _execute_context
    self._handle_dbapi_exception(
  File "/home/airflow/.local/lib/python3.12/site-packages/sqlalchemy/engine/base.py", line 2134, in _handle_dbapi_exception
    util.raise_(
  File "/home/airflow/.local/lib/python3.12/site-packages/sqlalchemy/util/compat.py", line 211, in raise_
    raise exception
  File "/home/airflow/.local/lib/python3.12/site-packages/sqlalchemy/engine/base.py", line 1910, in _execute_context
    self.dialect.do_execute(
  File "/home/airflow/.local/lib/python3.12/site-packages/sqlalchemy/engine/default.py", line 736, in do_execute
    cursor.execute(statement, parameters)
sqlalchemy.exc.IntegrityError: (psycopg2.errors.UniqueViolation) duplicate key value violates unique constraint "capsules_pkey"
DETAIL:  Key (id)=(5e9e2c5bf35918ed873b2664) already exists.

[SQL: INSERT INTO capsules (reuse_count, water_landings, land_landings, last_update, launches, serial, status, type, id) VALUES (%(reuse_count)s, %(water_landings)s, %(land_landings)s, %(last_update)s, %(launches)s::VARCHAR[], %(serial)s, %(status)s, %(type)s, %(id)s)]
[parameters: {'reuse_count': 0, 'water_landings': 1, 'land_landings': 0, 'last_update': 'Hanging in atrium at SpaceX HQ in Hawthorne ', 'launches': ['5eb87cdeffd86e000604b330'], 'serial': 'C101', 'status': 'retired', 'type': 'Dragon 1.0', 'id': '5e9e2c5bf35918ed873b2664'}]
(Background on this error at: https://sqlalche.me/e/14/gkpj)

During handling of the above exception, another exception occurred:

Traceback (most recent call last):
  File "/home/airflow/.local/lib/python3.12/site-packages/airflow/models/taskinstance.py", line 768, in _execute_task
    result = _execute_callable(context=context, **execute_callable_kwargs)
             ^^^^^^^^^^^^^^^^^^^^^^^^^^^^^^^^^^^^^^^^^^^^^^^^^^^^^^^^^^^^^
  File "/home/airflow/.local/lib/python3.12/site-packages/airflow/models/taskinstance.py", line 734, in _execute_callable
    return ExecutionCallableRunner(
           ^^^^^^^^^^^^^^^^^^^^^^^^
  File "/home/airflow/.local/lib/python3.12/site-packages/airflow/utils/operator_helpers.py", line 252, in run
    return self.func(*args, **kwargs)
           ^^^^^^^^^^^^^^^^^^^^^^^^^^
  File "/home/airflow/.local/lib/python3.12/site-packages/airflow/models/baseoperator.py", line 424, in wrapper
    return func(self, *args, **kwargs)
           ^^^^^^^^^^^^^^^^^^^^^^^^^^^
  File "/home/airflow/.local/lib/python3.12/site-packages/airflow/operators/python.py", line 238, in execute
    return_value = self.execute_callable()
                   ^^^^^^^^^^^^^^^^^^^^^^^
  File "/home/airflow/.local/lib/python3.12/site-packages/airflow/operators/python.py", line 256, in execute_callable
    return runner.run(*self.op_args, **self.op_kwargs)
           ^^^^^^^^^^^^^^^^^^^^^^^^^^^^^^^^^^^^^^^^^^^
  File "/home/airflow/.local/lib/python3.12/site-packages/airflow/utils/operator_helpers.py", line 252, in run
    return self.func(*args, **kwargs)
           ^^^^^^^^^^^^^^^^^^^^^^^^^^
  File "/opt/airflow/dags/main_dag.py", line 29, in load_data
    raise Exception(f"Ошикбка {e}")
Exception: Ошикбка (psycopg2.errors.UniqueViolation) duplicate key value violates unique constraint "capsules_pkey"
DETAIL:  Key (id)=(5e9e2c5bf35918ed873b2664) already exists.

[SQL: INSERT INTO capsules (reuse_count, water_landings, land_landings, last_update, launches, serial, status, type, id) VALUES (%(reuse_count)s, %(water_landings)s, %(land_landings)s, %(last_update)s, %(launches)s::VARCHAR[], %(serial)s, %(status)s, %(type)s, %(id)s)]
[parameters: {'reuse_count': 0, 'water_landings': 1, 'land_landings': 0, 'last_update': 'Hanging in atrium at SpaceX HQ in Hawthorne ', 'launches': ['5eb87cdeffd86e000604b330'], 'serial': 'C101', 'status': 'retired', 'type': 'Dragon 1.0', 'id': '5e9e2c5bf35918ed873b2664'}]
(Background on this error at: https://sqlalche.me/e/14/gkpj)
[2025-03-27T12:06:50.595+0000] {logging_mixin.py:190} INFO - Task instance in failure state
[2025-03-27T12:06:50.596+0000] {logging_mixin.py:190} INFO - Task start:2025-03-27 12:06:48.114613+00:00 end:2025-03-27 12:06:50.595233+00:00 duration:2.48062
[2025-03-27T12:06:50.596+0000] {logging_mixin.py:190} INFO - Task:<Task(PythonOperator): add_capsules_to_table> dag:<DAG: my_dag> dagrun:<DagRun my_dag @ 2025-03-27 12:06:46.350909+00:00: manual__2025-03-27T12:06:46.350909+00:00, state:running, queued_at: 2025-03-27 12:06:46.359295+00:00. externally triggered: True>
[2025-03-27T12:06:50.596+0000] {logging_mixin.py:190} INFO - Failure caused by Ошикбка (psycopg2.errors.UniqueViolation) duplicate key value violates unique constraint "capsules_pkey"
DETAIL:  Key (id)=(5e9e2c5bf35918ed873b2664) already exists.

[SQL: INSERT INTO capsules (reuse_count, water_landings, land_landings, last_update, launches, serial, status, type, id) VALUES (%(reuse_count)s, %(water_landings)s, %(land_landings)s, %(last_update)s, %(launches)s::VARCHAR[], %(serial)s, %(status)s, %(type)s, %(id)s)]
[parameters: {'reuse_count': 0, 'water_landings': 1, 'land_landings': 0, 'last_update': 'Hanging in atrium at SpaceX HQ in Hawthorne ', 'launches': ['5eb87cdeffd86e000604b330'], 'serial': 'C101', 'status': 'retired', 'type': 'Dragon 1.0', 'id': '5e9e2c5bf35918ed873b2664'}]
(Background on this error at: https://sqlalche.me/e/14/gkpj)
[2025-03-27T12:06:50.596+0000] {taskinstance.py:1226} INFO - Marking task as FAILED. dag_id=my_dag, task_id=add_capsules_to_table, run_id=manual__2025-03-27T12:06:46.350909+00:00, execution_date=20250327T120646, start_date=20250327T120648, end_date=20250327T120650
[2025-03-27T12:06:50.619+0000] {taskinstance.py:341} INFO - ::group::Post task execution logs
[2025-03-27T12:06:50.620+0000] {standard_task_runner.py:124} ERROR - Failed to execute job 32 for task add_capsules_to_table (Ошикбка (psycopg2.errors.UniqueViolation) duplicate key value violates unique constraint "capsules_pkey"
DETAIL:  Key (id)=(5e9e2c5bf35918ed873b2664) already exists.

[SQL: INSERT INTO capsules (reuse_count, water_landings, land_landings, last_update, launches, serial, status, type, id) VALUES (%(reuse_count)s, %(water_landings)s, %(land_landings)s, %(last_update)s, %(launches)s::VARCHAR[], %(serial)s, %(status)s, %(type)s, %(id)s)]
[parameters: {'reuse_count': 0, 'water_landings': 1, 'land_landings': 0, 'last_update': 'Hanging in atrium at SpaceX HQ in Hawthorne ', 'launches': ['5eb87cdeffd86e000604b330'], 'serial': 'C101', 'status': 'retired', 'type': 'Dragon 1.0', 'id': '5e9e2c5bf35918ed873b2664'}]
(Background on this error at: https://sqlalche.me/e/14/gkpj); 277)
Traceback (most recent call last):
  File "/home/airflow/.local/lib/python3.12/site-packages/sqlalchemy/engine/base.py", line 1910, in _execute_context
    self.dialect.do_execute(
  File "/home/airflow/.local/lib/python3.12/site-packages/sqlalchemy/engine/default.py", line 736, in do_execute
    cursor.execute(statement, parameters)
psycopg2.errors.UniqueViolation: duplicate key value violates unique constraint "capsules_pkey"
DETAIL:  Key (id)=(5e9e2c5bf35918ed873b2664) already exists.


The above exception was the direct cause of the following exception:

Traceback (most recent call last):
  File "/opt/airflow/dags/main_dag.py", line 24, in load_data
    session.commit()
  File "/home/airflow/.local/lib/python3.12/site-packages/sqlalchemy/orm/session.py", line 1454, in commit
    self._transaction.commit(_to_root=self.future)
  File "/home/airflow/.local/lib/python3.12/site-packages/sqlalchemy/orm/session.py", line 832, in commit
    self._prepare_impl()
  File "/home/airflow/.local/lib/python3.12/site-packages/sqlalchemy/orm/session.py", line 811, in _prepare_impl
    self.session.flush()
  File "/home/airflow/.local/lib/python3.12/site-packages/sqlalchemy/orm/session.py", line 3449, in flush
    self._flush(objects)
  File "/home/airflow/.local/lib/python3.12/site-packages/sqlalchemy/orm/session.py", line 3588, in _flush
    with util.safe_reraise():
         ^^^^^^^^^^^^^^^^^^^
  File "/home/airflow/.local/lib/python3.12/site-packages/sqlalchemy/util/langhelpers.py", line 70, in __exit__
    compat.raise_(
  File "/home/airflow/.local/lib/python3.12/site-packages/sqlalchemy/util/compat.py", line 211, in raise_
    raise exception
  File "/home/airflow/.local/lib/python3.12/site-packages/sqlalchemy/orm/session.py", line 3549, in _flush
    flush_context.execute()
  File "/home/airflow/.local/lib/python3.12/site-packages/sqlalchemy/orm/unitofwork.py", line 456, in execute
    rec.execute(self)
  File "/home/airflow/.local/lib/python3.12/site-packages/sqlalchemy/orm/unitofwork.py", line 630, in execute
    util.preloaded.orm_persistence.save_obj(
  File "/home/airflow/.local/lib/python3.12/site-packages/sqlalchemy/orm/persistence.py", line 245, in save_obj
    _emit_insert_statements(
  File "/home/airflow/.local/lib/python3.12/site-packages/sqlalchemy/orm/persistence.py", line 1097, in _emit_insert_statements
    c = connection._execute_20(
        ^^^^^^^^^^^^^^^^^^^^^^^
  File "/home/airflow/.local/lib/python3.12/site-packages/sqlalchemy/engine/base.py", line 1710, in _execute_20
    return meth(self, args_10style, kwargs_10style, execution_options)
           ^^^^^^^^^^^^^^^^^^^^^^^^^^^^^^^^^^^^^^^^^^^^^^^^^^^^^^^^^^^
  File "/home/airflow/.local/lib/python3.12/site-packages/sqlalchemy/sql/elements.py", line 334, in _execute_on_connection
    return connection._execute_clauseelement(
           ^^^^^^^^^^^^^^^^^^^^^^^^^^^^^^^^^^
  File "/home/airflow/.local/lib/python3.12/site-packages/sqlalchemy/engine/base.py", line 1577, in _execute_clauseelement
    ret = self._execute_context(
          ^^^^^^^^^^^^^^^^^^^^^^
  File "/home/airflow/.local/lib/python3.12/site-packages/sqlalchemy/engine/base.py", line 1953, in _execute_context
    self._handle_dbapi_exception(
  File "/home/airflow/.local/lib/python3.12/site-packages/sqlalchemy/engine/base.py", line 2134, in _handle_dbapi_exception
    util.raise_(
  File "/home/airflow/.local/lib/python3.12/site-packages/sqlalchemy/util/compat.py", line 211, in raise_
    raise exception
  File "/home/airflow/.local/lib/python3.12/site-packages/sqlalchemy/engine/base.py", line 1910, in _execute_context
    self.dialect.do_execute(
  File "/home/airflow/.local/lib/python3.12/site-packages/sqlalchemy/engine/default.py", line 736, in do_execute
    cursor.execute(statement, parameters)
sqlalchemy.exc.IntegrityError: (psycopg2.errors.UniqueViolation) duplicate key value violates unique constraint "capsules_pkey"
DETAIL:  Key (id)=(5e9e2c5bf35918ed873b2664) already exists.

[SQL: INSERT INTO capsules (reuse_count, water_landings, land_landings, last_update, launches, serial, status, type, id) VALUES (%(reuse_count)s, %(water_landings)s, %(land_landings)s, %(last_update)s, %(launches)s::VARCHAR[], %(serial)s, %(status)s, %(type)s, %(id)s)]
[parameters: {'reuse_count': 0, 'water_landings': 1, 'land_landings': 0, 'last_update': 'Hanging in atrium at SpaceX HQ in Hawthorne ', 'launches': ['5eb87cdeffd86e000604b330'], 'serial': 'C101', 'status': 'retired', 'type': 'Dragon 1.0', 'id': '5e9e2c5bf35918ed873b2664'}]
(Background on this error at: https://sqlalche.me/e/14/gkpj)

During handling of the above exception, another exception occurred:

Traceback (most recent call last):
  File "/home/airflow/.local/lib/python3.12/site-packages/airflow/task/task_runner/standard_task_runner.py", line 117, in _start_by_fork
    ret = args.func(args, dag=self.dag)
          ^^^^^^^^^^^^^^^^^^^^^^^^^^^^^
  File "/home/airflow/.local/lib/python3.12/site-packages/airflow/cli/cli_config.py", line 49, in command
    return func(*args, **kwargs)
           ^^^^^^^^^^^^^^^^^^^^^
  File "/home/airflow/.local/lib/python3.12/site-packages/airflow/utils/cli.py", line 116, in wrapper
    return f(*args, **kwargs)
           ^^^^^^^^^^^^^^^^^^
  File "/home/airflow/.local/lib/python3.12/site-packages/airflow/cli/commands/task_command.py", line 483, in task_run
    task_return_code = _run_task_by_selected_method(args, _dag, ti)
                       ^^^^^^^^^^^^^^^^^^^^^^^^^^^^^^^^^^^^^^^^^^^^
  File "/home/airflow/.local/lib/python3.12/site-packages/airflow/cli/commands/task_command.py", line 256, in _run_task_by_selected_method
    return _run_raw_task(args, ti)
           ^^^^^^^^^^^^^^^^^^^^^^^
  File "/home/airflow/.local/lib/python3.12/site-packages/airflow/cli/commands/task_command.py", line 341, in _run_raw_task
    return ti._run_raw_task(
           ^^^^^^^^^^^^^^^^^
  File "/home/airflow/.local/lib/python3.12/site-packages/airflow/utils/session.py", line 97, in wrapper
    return func(*args, session=session, **kwargs)
           ^^^^^^^^^^^^^^^^^^^^^^^^^^^^^^^^^^^^^^
  File "/home/airflow/.local/lib/python3.12/site-packages/airflow/models/taskinstance.py", line 3006, in _run_raw_task
    return _run_raw_task(
           ^^^^^^^^^^^^^^
  File "/home/airflow/.local/lib/python3.12/site-packages/airflow/models/taskinstance.py", line 274, in _run_raw_task
    TaskInstance._execute_task_with_callbacks(
  File "/home/airflow/.local/lib/python3.12/site-packages/airflow/models/taskinstance.py", line 3161, in _execute_task_with_callbacks
    result = self._execute_task(context, task_orig)
             ^^^^^^^^^^^^^^^^^^^^^^^^^^^^^^^^^^^^^^
  File "/home/airflow/.local/lib/python3.12/site-packages/airflow/models/taskinstance.py", line 3185, in _execute_task
    return _execute_task(self, context, task_orig)
           ^^^^^^^^^^^^^^^^^^^^^^^^^^^^^^^^^^^^^^^
  File "/home/airflow/.local/lib/python3.12/site-packages/airflow/models/taskinstance.py", line 768, in _execute_task
    result = _execute_callable(context=context, **execute_callable_kwargs)
             ^^^^^^^^^^^^^^^^^^^^^^^^^^^^^^^^^^^^^^^^^^^^^^^^^^^^^^^^^^^^^
  File "/home/airflow/.local/lib/python3.12/site-packages/airflow/models/taskinstance.py", line 734, in _execute_callable
    return ExecutionCallableRunner(
           ^^^^^^^^^^^^^^^^^^^^^^^^
  File "/home/airflow/.local/lib/python3.12/site-packages/airflow/utils/operator_helpers.py", line 252, in run
    return self.func(*args, **kwargs)
           ^^^^^^^^^^^^^^^^^^^^^^^^^^
  File "/home/airflow/.local/lib/python3.12/site-packages/airflow/models/baseoperator.py", line 424, in wrapper
    return func(self, *args, **kwargs)
           ^^^^^^^^^^^^^^^^^^^^^^^^^^^
  File "/home/airflow/.local/lib/python3.12/site-packages/airflow/operators/python.py", line 238, in execute
    return_value = self.execute_callable()
                   ^^^^^^^^^^^^^^^^^^^^^^^
  File "/home/airflow/.local/lib/python3.12/site-packages/airflow/operators/python.py", line 256, in execute_callable
    return runner.run(*self.op_args, **self.op_kwargs)
           ^^^^^^^^^^^^^^^^^^^^^^^^^^^^^^^^^^^^^^^^^^^
  File "/home/airflow/.local/lib/python3.12/site-packages/airflow/utils/operator_helpers.py", line 252, in run
    return self.func(*args, **kwargs)
           ^^^^^^^^^^^^^^^^^^^^^^^^^^
  File "/opt/airflow/dags/main_dag.py", line 29, in load_data
    raise Exception(f"Ошикбка {e}")
Exception: Ошикбка (psycopg2.errors.UniqueViolation) duplicate key value violates unique constraint "capsules_pkey"
DETAIL:  Key (id)=(5e9e2c5bf35918ed873b2664) already exists.

[SQL: INSERT INTO capsules (reuse_count, water_landings, land_landings, last_update, launches, serial, status, type, id) VALUES (%(reuse_count)s, %(water_landings)s, %(land_landings)s, %(last_update)s, %(launches)s::VARCHAR[], %(serial)s, %(status)s, %(type)s, %(id)s)]
[parameters: {'reuse_count': 0, 'water_landings': 1, 'land_landings': 0, 'last_update': 'Hanging in atrium at SpaceX HQ in Hawthorne ', 'launches': ['5eb87cdeffd86e000604b330'], 'serial': 'C101', 'status': 'retired', 'type': 'Dragon 1.0', 'id': '5e9e2c5bf35918ed873b2664'}]
(Background on this error at: https://sqlalche.me/e/14/gkpj)
[2025-03-27T12:06:50.660+0000] {local_task_job_runner.py:266} INFO - Task exited with return code 1
[2025-03-27T12:06:50.845+0000] {taskinstance.py:3901} INFO - 0 downstream tasks scheduled from follow-on schedule check
[2025-03-27T12:06:50.856+0000] {local_task_job_runner.py:245} INFO - ::endgroup::
